<?xml version="1.0"?>

<sdf version="1.6">
  <model name="ISR_M2">
    <pose>0.0 0.0 0.0 0.0 0.0 0.0</pose>

    <link name="base_footprint"/>

    <link name='base_link'>
      <pose>0.0 0.0 0.16 0.0 0.0 0.0 0.0</pose>
      <inertial>
        <mass>1</mass>
        <inertia>
          <ixx>0.166667</ixx>
          <ixy>0.0</ixy>
          <ixz>0.0</ixz>
          <iyy>0.166667</iyy>
          <iyz>0.0</iyz>
          <izz>0.166667</izz>
        </inertia>
      </inertial>
      <visual name='visual'>
        <pose>-0.2 0.0 0.065 0.0 0.0 0.0 0.0</pose>
        <geometry>
          <box>
            <size>0.6 0.4 0.25</size>
          </box>
        </geometry>
      </visual>
      <collision name='collision'>
        <pose>-0.2 0.0 0.065 0.0 0.0 0.0 0.0</pose>
        <geometry>
          <box>
            <size>0.6 0.4 0.25</size>
          </box>
        </geometry>
      </collision>
    </link>

    <link name='left_wheel'>
      <pose>0.0 0.25 0.16 1.5707 0 0</pose>
      <inertial>
        <mass>1</mass>
        <inertia>
          <ixx>0.145833</ixx>
          <ixy>0</ixy>
          <ixz>0</ixz>
          <iyy>0.145833</iyy>
          <iyz>0</iyz>
          <izz>0.125</izz>
        </inertia>
      </inertial>
      <visual name='visual'>
        <geometry>
          <cylinder>
            <radius>0.16</radius>
            <length>0.10</length>
          </cylinder>
        </geometry>
      </visual>
      <collision name='collision'>
        <geometry>
          <cylinder>
            <radius>0.16</radius>
            <length>0.10</length>
          </cylinder>
        </geometry>
        <surface>
          <friction>
            <ode>
              <mu>1</mu>
              <mu2>1</mu2>
              <slip1>0</slip1>
              <slip2>0</slip2>
            </ode>
          </friction>
          <contact>
            <ode>
              <soft_cfm>0</soft_cfm>
              <soft_erp>0.2</soft_erp>
              <kp>1e+13</kp>
              <kd>1</kd>
              <max_vel>0.01</max_vel>
              <min_depth>0.01</min_depth>
            </ode>
          </contact>
        </surface>
      </collision>
    </link>

    <link name='right_wheel'>
      <pose>0.0 -0.25 0.16 1.5707 0 0</pose>
      <inertial>
        <mass>1</mass>
        <inertia>
          <ixx>0.145833</ixx>
          <ixy>0</ixy>
          <ixz>0</ixz>
          <iyy>0.145833</iyy>
          <iyz>0</iyz>
          <izz>0.125</izz>
        </inertia>
      </inertial>
      <visual name='visual'>
        <geometry>
          <cylinder>
            <radius>0.16</radius>
            <length>0.10</length>
          </cylinder>
        </geometry>
      </visual>
      <collision name='collision'>
        <geometry>
          <cylinder>
            <radius>0.16</radius>
            <length>0.10</length>
          </cylinder>
        </geometry>
        <surface>
          <friction>
            <ode>
              <mu>1</mu>
              <mu2>1</mu2>
              <slip1>0</slip1>
              <slip2>0</slip2>
            </ode>
          </friction>
          <contact>
            <ode>
              <soft_cfm>0</soft_cfm>
              <soft_erp>0.2</soft_erp>
              <kp>1e+13</kp>
              <kd>1</kd>
              <max_vel>0.01</max_vel>
              <min_depth>0.01</min_depth>
            </ode>
          </contact>
        </surface>
      </collision>
    </link>

    <link name='caster'>
      <pose>-0.45 0 0.09 0 -0 0</pose>
      <inertial>
        <mass>1</mass>
        <inertia>
          <ixx>0.1</ixx>
          <ixy>0</ixy>
          <ixz>0</ixz>
          <iyy>0.1</iyy>
          <iyz>0</iyz>
          <izz>0.1</izz>
        </inertia>
      </inertial>
      <visual name='visual'>
        <geometry>
          <sphere>
            <radius>0.09</radius>
          </sphere>
        </geometry>
      </visual>
      <collision name='collision'>
        <geometry>
          <sphere>
            <radius>0.09</radius>
          </sphere>
        </geometry>
      </collision>
    </link>

    <link name='hokuyo'>
      <pose>0.05 0 0.38 0 0 0</pose>
      <inertial>
        <mass>0.1</mass>
      </inertial>

      <visual name='visual'>
        <geometry>
          <mesh>
            <uri>model://hokuyo/meshes/hokuyo.dae</uri>
          </mesh>
        </geometry>
      </visual>

      <collision name='collision-base'>
        <geometry>
          <box>
            <size>0.05 0.05 0.041</size>
          </box>
        </geometry>
      </collision>

      <collision name='collision-top'>
        <geometry>
          <cylinder>
            <radius>0.021</radius>
            <length>0.029</length>
          </cylinder>
        </geometry>
      </collision>

      <sensor name='laser' type='ray'>
        <always_on>true</always_on>
        <visualize>false</visualize>
        <pose>0 0 0 0 0 0</pose>
        <update_rate>10</update_rate>
        <ray>
          <scan>
            <horizontal>
              <samples>640</samples>
              <resolution>1</resolution>
              <min_angle>-2.26889</min_angle>
              <max_angle>2.2689</max_angle>
            </horizontal>
          </scan>
          <range>
            <min>0.08</min>
            <max>10</max>
            <resolution>0.01</resolution>
          </range>
        </ray>
        <plugin name='laserscan' filename='libgazebo_ros_ray_sensor.so'>
          <ros>
            <remapping>~/out:=scan</remapping>
          </ros>
          <output_type>sensor_msgs/LaserScan</output_type>
          <!-- Manual -->
          <frame_name>Robot2/hokuyo</frame_name>
        </plugin>
      </sensor>
    </link>

    <joint name="base_joint" type="fixed">
      <parent>base_footprint</parent>
      <child>base_link</child>
      <pose>0.0 0.0 0.0 0.0 0.0 0.0</pose>
    </joint>

    <joint name='left_wheel_joint' type='revolute'>
      <parent>base_link</parent>
      <child>left_wheel</child>
      <axis>
        <xyz>0 0 -1</xyz>
        <limit>
          <lower>-1.79769e+308</lower>
          <upper>1.79769e+308</upper>
        </limit>
      </axis>
    </joint>

    <joint name='right_wheel_joint' type='revolute'>
      <parent>base_link</parent>
      <child>right_wheel</child>
      <axis>
        <xyz>0 0 -1</xyz>
        <limit>
          <lower>-1.79769e+308</lower>
          <upper>1.79769e+308</upper>
        </limit>
      </axis>
    </joint>

    <joint name='caster_wheel' type='ball'>
      <parent>base_link</parent>
      <child>caster</child>
    </joint>

    <joint name='hokuyo_joint' type='fixed'>
      <parent>base_link</parent>
      <child>hokuyo</child>
      <pose>0.05 0 0.38 0 0 0</pose>
      <axis>
        <xyz>0 0 1</xyz>
      </axis>
    </joint>

    <plugin name='diff_drive' filename='libgazebo_ros_diff_drive.so'>

      <!-- wheels -->
      <left_joint>left_wheel_joint</left_joint>
      <right_joint>right_wheel_joint</right_joint>

      <!-- kinematics -->
      <wheel_separation>0.5</wheel_separation>
      <wheel_diameter>0.32</wheel_diameter>

      <!-- limits -->
      <max_wheel_torque>20</max_wheel_torque>
      <max_wheel_acceleration>1.0</max_wheel_acceleration>

      <!-- output -->
      <publish_odom>true</publish_odom>
      <publish_odom_tf>false</publish_odom_tf>
      <publish_wheel_tf>false</publish_wheel_tf>

      <odometry_topic>odom</odometry_topic>
      <!-- Manual -->
      <odometry_frame>Robot2/odom</odometry_frame>
      <robot_base_frame>Robot2/base_footprint</robot_base_frame>

    </plugin>

    <plugin name="ISR_M2_joint_state" filename = "libgazebo_ros_joint_state_publisher.so">
      <ros>
        <remapping>~/out:=joint_states</remapping>
      </ros>
      <joint_name>Robot2/left_wheel_joint</joint_name>
      <joint_name>Robot2/right_wheel_joint</joint_name>
    </plugin>

  </model>
</sdf>